Workbook

Sheet Main
A1: 2023 Gaz | B1: 2024 Gaz | C1: 2025 Gaz | D1: 2023 Elektr | E1: 2024 Elektr | F1: 2025 Elektr | G1: 2026 Elektr | H1: 2023 Boshqa | I1: 2024 Boshqa | J1: 2025 Boshqa
A2: 127 | B2: 127 | C2: 127 | D2: 127 | E2: 127 | F2: 127 | G2: 127 | H2: 127 | I2: 127 | J2: 127
A3: 130 | B3: 130 | C3: 130 | D3: 130 | E3: 130 | F3: 130 | G3: 130 | H3: 130 | I3: 130 | J3: 130
A4: 159 | B4: 159 | C4: 159 | D4: 159 | E4: 159 | F4: 159 | G4: 159 | H4: 159 | I4: 159 | J4: 159
A5: 191 | B5: 191 | C5: 191 | D5: 191 | E5: 191 | F5: 191 | G5: 191 | H5: 191 | I5: 191 | J5: 191
A6: 180 | B6: 180 | C6: 180 | D6: 180 | E6: 180 | F6: 180 | G6: 180 | H6: 180 | I6: 180 | J6: 180
A7: 176 | B7: 176 | C7: 176 | D7: 176 | E7: 176 | F7: 176 | G7: 176 | H7: 176 | I7: 176 | J7: 176
A8: 179 | B8: 179 | C8: 179 | D8: 179 | E8: 179 | F8: 179 | G8: 179 | H8: 179 | I8: 179 | J8: 179
A9: 74 | B9: 74 | C9: 74 | D9: 74 | E9: 74 | F9: 74 | G9: 74 | H9: 74 | I9: 74 | J9: 74
A10: 99 | B10: 99 | C10: 99 | D10: 99 | E10: 99 | F10: 99 | G10: 99 | H10: 99 | I10: 99 | J10: 99
A11: 131 | B11: 131 | C11: 131 | D11: 131 | E11: 131 | F11: 131 | G11: 131 | H11: 131 | I11: 131 | J11: 131
A12: 126 | B12: 126 | C12: 126 | D12: 126 | E12: 126 | F12: 126 | G12: 126 | H12: 126 | I12: 126 | J12: 126
A13: 144 | B13: 144 | C13: 144 | D13: 144 | E13: 144 | F13: 144 | G13: 144 | H13: 144 | I13: 144 | J13: 144
A15: 2023–YIL UCHUN ENERGIYA ISTE’MOLI TAHLILI
A16: Oy | B16: Elektr (kWh) | C16: Gaz iste'moli (m³) | D16: Gaz energiyasi (kwt/soat) | E16: Boshqa turdagi e. Iste'mol (kg) | F16: Boshqa turdagi e. kwt/soat | G16: Jami (kwt/soat)
A17: Yanvar | B17: =Energy_calc!B4 -> 127 | C17: =Energy_calc!F4 -> 127 | D17: =Energy_calc!G4 -> 1206.5 | E17: 0 | F17: =E17*6.98 -> 0 | G17: =B17+D17+F17 -> 1333.5
A18: Fevral | B18: =Energy_calc!B5 -> 130 | C18: =Energy_calc!F5 -> 130 | D18: =Energy_calc!G5 -> 1235 | E18: 0 | F18: =E18*6.98 -> 0 | G18: =B18+D18+F18 -> 1365
A19: Mart | B19: =Energy_calc!B6 -> 159 | C19: =Energy_calc!F6 -> 159 | D19: =Energy_calc!G6 -> 1510.5 | E19: 0 | F19: =E19*6.98 -> 0 | G19: =B19+D19+F19 -> 1669.5
A20: Aprel | B20: =Energy_calc!B7 -> 191 | C20: =Energy_calc!F7 -> 191 | D20: =Energy_calc!G7 -> 1814.5 | E20: 0 | F20: =E20*6.98 -> 0 | G20: =B20+D20+F20 -> 2005.5
A21: May | B21: =Energy_calc!B8 -> 180 | C21: =Energy_calc!F8 -> 180 | D21: =Energy_calc!G8 -> 1710 | E21: 0 | F21: =E21*6.98 -> 0 | G21: =B21+D21+F21 -> 1890
A22: Iyun | B22: =Energy_calc!B9 -> 176 | C22: =Energy_calc!F9 -> 176 | D22: =Energy_calc!G9 -> 1672 | E22: 0 | F22: =E22*6.98 -> 0 | G22: =B22+D22+F22 -> 1848
A23: Iyul | B23: =Energy_calc!B10 -> 179 | C23: =Energy_calc!F10 -> 179 | D23: =Energy_calc!G10 -> 1700.5 | E23: 0 | F23: =E23*6.98 -> 0 | G23: =B23+D23+F23 -> 1879.5
A24: Avgust | B24: =Energy_calc!B11 -> 74 | C24: =Energy_calc!F11 -> 74 | D24: =Energy_calc!G11 -> 703 | E24: 0 | F24: =E24*6.98 -> 0 | G24: =B24+D24+F24 -> 777
A25: Sentabr | B25: =Energy_calc!B12 -> 99 | C25: =Energy_calc!F12 -> 99 | D25: =Energy_calc!G12 -> 940.5 | E25: 0 | F25: =E25*6.98 -> 0 | G25: =B25+D25+F25 -> 1039.5
A26: Oktyabr | B26: =Energy_calc!B13 -> 131 | C26: =Energy_calc!F13 -> 131 | D26: =Energy_calc!G13 -> 1244.5 | E26: 0 | F26: =E26*6.98 -> 0 | G26: =B26+D26+F26 -> 1375.5
A27: Noyabr | B27: =Energy_calc!B14 -> 126 | C27: =Energy_calc!F14 -> 126 | D27: =Energy_calc!G14 -> 1197 | E27: 0 | F27: =E27*6.98 -> 0 | G27: =B27+D27+F27 -> 1323
A28: Dekabr | B28: =Energy_calc!B15 -> 144 | C28: =Energy_calc!F15 -> 144 | D28: =Energy_calc!G15 -> 1368 | E28: 0 | F28: =E28*6.98 -> 0 | G28: =B28+D28+F28 -> 1512
A29: JAMI | B29: =Energy_calc!B16 -> 1716 | C29: =Energy_calc!F16 -> 1716 | D29: =Energy_calc!G16 -> 16302 | E29: =SUM(E17:E28) -> 0 | F29: =SUM(F17:F28) -> 0 | G29: =B29+D29+F29 -> 18018
A30: JAMI yillik energiya sarfi: | C30: =Main!K76 -> 29995.68 | D30: kW*soat
A31: Ulushi: | B31: =Main!M76 -> 0.54347826 | C31: gaz; | D31: =Main!L76 -> 0.057208238 | E31: elektr; | F31: =Main!N76 -> 0.3993135 | G31: boshqa t.
A32: Yillik umumiy xarajatlar: | C32: =Main!O76/1000000 -> 2.8743 | D32: mln. So'm
A34: 2024–YIL UCHUN ENERGIYA ISTE’MOLI TAHLILI
A35: Oy | B35: Elektr (kWh) | C35: Gaz iste'moli (m³) | D35: Gaz energiyasi (kwt/soat) | E35: Boshqa turdagi e. Iste'mol (kg) | F35: Boshqa turdagi e. kwt/soat | G35: Jami (kwt/soat)
A36: Yanvar | B36: =Energy_calc!B26 -> 127 | C36: =Energy_calc!L26 -> 127 | D36: =Energy_calc!M26 -> 1206.5 | E36: =Energy_calc!W26 -> 127 | F36: =Energy_calc!X26 -> 886.46 | G36: =B36+D36+F36 -> 2219.96
A37: Fevral | B37: =Energy_calc!B27 -> 130 | C37: =Energy_calc!L27 -> 130 | D37: =Energy_calc!M27 -> 1235 | E37: =Energy_calc!W27 -> 130 | F37: =Energy_calc!X27 -> 907.4 | G37: =B37+D37+F37 -> 2272.4
A38: Mart | B38: =Energy_calc!B28 -> 159 | C38: =Energy_calc!L28 -> 159 | D38: =Energy_calc!M28 -> 1510.5 | E38: =Energy_calc!W28 -> 159 | F38: =Energy_calc!X28 -> 1109.82 | G38: =B38+D38+F38 -> 2779.32
A39: Aprel | B39: =Energy_calc!B29 -> 191 | C39: =Energy_calc!L29 -> 191 | D39: =Energy_calc!M29 -> 1814.5 | E39: =Energy_calc!W29 -> 191 | F39: =Energy_calc!X29 -> 1333.18 | G39: =B39+D39+F39 -> 3338.68
A40: May | B40: =Energy_calc!B30 -> 180 | C40: =Energy_calc!L30 -> 180 | D40: =Energy_calc!M30 -> 1710 | E40: =Energy_calc!W30 -> 180 | F40: =Energy_calc!X30 -> 1256.4 | G40: =B40+D40+F40 -> 3146.4
A41: Iyun | B41: =Energy_calc!B31 -> 176 | C41: =Energy_calc!L31 -> 176 | D41: =Energy_calc!M31 -> 1672 | E41: =Energy_calc!W31 -> 176 | F41: =Energy_calc!X31 -> 1228.48 | G41: =B41+D41+F41 -> 3076.48
A42: Iyul | B42: =Energy_calc!B32 -> 179 | C42: =Energy_calc!L32 -> 179 | D42: =Energy_calc!M32 -> 1700.5 | E42: =Energy_calc!W32 -> 179 | F42: =Energy_calc!X32 -> 1249.42 | G42: =B42+D42+F42 -> 3128.92
...

Sheet Area_calc
A1: Total area | E1: Windows
A2: dimensions | B2: dimensions2 | C2: section_area | E2: dimensions | F2: dimensions2 | G2: number | H2: window_area
A3: 8 | B3: 4 | C3: =Table2[[#This Row],[dimensions]]*Table2[[#This Row],[dimensions2]] -> 32 | E3: 2 | F3: 1.2 | G3: 10 | H3: =Table24[[#This Row],[dimensions]]*Table24[[#This Row],[dimensions2]]*Table24[[#This Row],[number]] -> 24
A4: 15 | B4: 3.5 | C4: =Table2[[#This Row],[dimensions]]*Table2[[#This Row],[dimensions2]] -> 52.5 | E4: 2.6 | F4: 1 | G4: 5 | H4: =Table24[[#This Row],[dimensions]]*Table24[[#This Row],[dimensions2]]*Table24[[#This Row],[number]] -> 13
A5: 13 | B5: 3.5 | C5: =Table2[[#This Row],[dimensions]]*Table2[[#This Row],[dimensions2]] -> 45.5 | E5: 0 | F5: 0 | G5: 0 | H5: =Table24[[#This Row],[dimensions]]*Table24[[#This Row],[dimensions2]]*Table24[[#This Row],[number]] -> 0
C6: =Table2[[#This Row],[dimensions]]*Table2[[#This Row],[dimensions2]] -> 0 | H6: =Table24[[#This Row],[dimensions]]*Table24[[#This Row],[dimensions2]]*Table24[[#This Row],[number]] -> 0
C7: =Table2[[#This Row],[dimensions]]*Table2[[#This Row],[dimensions2]] -> 0 | H7: =Table24[[#This Row],[dimensions]]*Table24[[#This Row],[dimensions2]]*Table24[[#This Row],[number]] -> 0
C8: =Table2[[#This Row],[dimensions]]*Table2[[#This Row],[dimensions2]] -> 0 | H8: =Table24[[#This Row],[dimensions]]*Table24[[#This Row],[dimensions2]]*Table24[[#This Row],[number]] -> 0
C9: =Table2[[#This Row],[dimensions]]*Table2[[#This Row],[dimensions2]] -> 0 | H9: =Table24[[#This Row],[dimensions]]*Table24[[#This Row],[dimensions2]]*Table24[[#This Row],[number]] -> 0
C10: =Table2[[#This Row],[dimensions]]*Table2[[#This Row],[dimensions2]] -> 0 | H10: =Table24[[#This Row],[dimensions]]*Table24[[#This Row],[dimensions2]]*Table24[[#This Row],[number]] -> 0
C11: =Table2[[#This Row],[dimensions]]*Table2[[#This Row],[dimensions2]] -> 0 | H11: =Table24[[#This Row],[dimensions]]*Table24[[#This Row],[dimensions2]]*Table24[[#This Row],[number]] -> 0
C12: =Table2[[#This Row],[dimensions]]*Table2[[#This Row],[dimensions2]] -> 0 | H12: =Table24[[#This Row],[dimensions]]*Table24[[#This Row],[dimensions2]]*Table24[[#This Row],[number]] -> 0
C13: =Table2[[#This Row],[dimensions]]*Table2[[#This Row],[dimensions2]] -> 0 | H13: =Table24[[#This Row],[dimensions]]*Table24[[#This Row],[dimensions2]]*Table24[[#This Row],[number]] -> 0
C14: =Table2[[#This Row],[dimensions]]*Table2[[#This Row],[dimensions2]] -> 0 | H14: =Table24[[#This Row],[dimensions]]*Table24[[#This Row],[dimensions2]]*Table24[[#This Row],[number]] -> 0
A15: total | C15: =SUM(C3:C14) -> 130 | E15: total | H15: =SUM(H3:H14) -> 37
A17: Walls | E17: Doors
A18: dimensions | B18: height | C18: wall_area | E18: dimensions | F18: dimensions2 | G18: number | H18: door_area
A19: 8 | C19: =Table26[[#This Row],[dimensions]]*Table26[[#This Row],[height]] -> 0 | E19: 2.6 | F19: 1 | G19: 5 | H19: =Table245[[#This Row],[dimensions]]*Table245[[#This Row],[dimensions2]]*Table245[[#This Row],[number]] -> 13
A20: 4 | C20: =Table26[[#This Row],[dimensions]]*Table26[[#This Row],[height]] -> 0 | E20: 0 | F20: 0 | G20: 0 | H20: =Table245[[#This Row],[dimensions]]*Table245[[#This Row],[dimensions2]]*Table245[[#This Row],[number]] -> 0
A21: =SUM(A19:A20) -> 12 | B21: 3 | C21: =Table26[[#This Row],[dimensions]]*Table26[[#This Row],[height]]*2 -> 72 | H21: =Table245[[#This Row],[dimensions]]*Table245[[#This Row],[dimensions2]]*Table245[[#This Row],[number]] -> 0
A22: 15 | C22: =Table26[[#This Row],[dimensions]]*Table26[[#This Row],[height]] -> 0 | H22: =Table245[[#This Row],[dimensions]]*Table245[[#This Row],[dimensions2]]*Table245[[#This Row],[number]] -> 0
A23: 3.5 | C23: =Table26[[#This Row],[dimensions]]*Table26[[#This Row],[height]] -> 0 | H23: =Table245[[#This Row],[dimensions]]*Table245[[#This Row],[dimensions2]]*Table245[[#This Row],[number]] -> 0
A24: =SUM(A22:A23) -> 18.5 | B24: 3 | C24: =Table26[[#This Row],[dimensions]]*Table26[[#This Row],[height]]*2 -> 111 | H24: =Table245[[#This Row],[dimensions]]*Table245[[#This Row],[dimensions2]]*Table245[[#This Row],[number]] -> 0
A25: 0 | C25: =Table26[[#This Row],[dimensions]]*Table26[[#This Row],[height]] -> 0 | H25: =Table245[[#This Row],[dimensions]]*Table245[[#This Row],[dimensions2]]*Table245[[#This Row],[number]] -> 0
A26: 0 | C26: =Table26[[#This Row],[dimensions]]*Table26[[#This Row],[height]] -> 0 | H26: =Table245[[#This Row],[dimensions]]*Table245[[#This Row],[dimensions2]]*Table245[[#This Row],[number]] -> 0
A27: =SUM(A25:A26) -> 0 | B27: 3.3 | C27: =Table26[[#This Row],[dimensions]]*Table26[[#This Row],[height]]*2 -> 0 | H27: =Table245[[#This Row],[dimensions]]*Table245[[#This Row],[dimensions2]]*Table245[[#This Row],[number]] -> 0
A28: 0 | B28: 0 | C28: 0 | H28: =Table245[[#This Row],[dimensions]]*Table245[[#This Row],[dimensions2]]*Table245[[#This Row],[number]] -> 0
A29: 0 | B29: 0 | C29: 0 | H29: =Table245[[#This Row],[dimensions]]*Table245[[#This Row],[dimensions2]]*Table245[[#This Row],[number]] -> 0
A30: 0 | B30: 0 | C30: 0 | H30: =Table245[[#This Row],[dimensions]]*Table245[[#This Row],[dimensions2]]*Table245[[#This Row],[number]] -> 0
C31: =Table26[[#This Row],[dimensions]]*Table26[[#This Row],[height]] -> 0 | E31: total | H31: =SUM(H19:H30) -> 13
C32: =Table26[[#This Row],[dimensions]]*Table26[[#This Row],[height]] -> 0
A33: =SUM(A31:A32) -> 0 | B33: 5.5 | C33: =Table26[[#This Row],[dimensions]]*Table26[[#This Row],[height]]*2 -> 0
A34: total | C34: =SUM(C19:C33)-H15-H31 -> 133
A36: Roof | B36: =C15*1.15 -> 149.5

Sheet Energy_calc
A1: 2023
A2: ELEKTR 2023 (tarif: 295 so'm/kWh) | E2: GAZ 2023 — Yagona flat tarif: 380 so'm/m³ | V2: Boshqa 2023 — Flat 1000 so'm/kg
A3: Oy | B3: Iste'mol (kWh) | C3: Xarajat (so'm) | E3: Oy | F3: Iste'mol (m³) | G3: energiya (kwt/soat) | H3: Xarajat (so'm) | V3: Oy | W3: Iste'mol (kg) | X3: kwt/soat | Y3: Xarajat (so'm)
A4: Yanvar | B4: =Main!D2 -> 127 | C4: =B4*295 -> 37465 | E4: Yanvar | F4: =Main!A2 -> 127 | G4: =F4*9.5 -> 1206.5 | H4: =F4*380 -> 48260 | V4: Yanvar | W4: =Main!H2 -> 127 | X4: =W4*6.98 -> 886.46 | Y4: =W4*1000 -> 127000
A5: Fevral | B5: =Main!D3 -> 130 | C5: =B5*295 -> 38350 | E5: Fevral | F5: =Main!A3 -> 130 | G5: =F5*9.5 -> 1235 | H5: =F5*380 -> 49400 | V5: Fevral | W5: =Main!H3 -> 130 | X5: =W5*6.98 -> 907.4 | Y5: =W5*1000 -> 130000
A6: Mart | B6: =Main!D4 -> 159 | C6: =B6*295 -> 46905 | E6: Mart | F6: =Main!A4 -> 159 | G6: =F6*9.5 -> 1510.5 | H6: =F6*380 -> 60420 | V6: Mart | W6: =Main!H4 -> 159 | X6: =W6*6.98 -> 1109.82 | Y6: =W6*1000 -> 159000
A7: Aprel | B7: =Main!D5 -> 191 | C7: =B7*295 -> 56345 | E7: Aprel | F7: =Main!A5 -> 191 | G7: =F7*9.5 -> 1814.5 | H7: =F7*380 -> 72580 | V7: Aprel | W7: =Main!H5 -> 191 | X7: =W7*6.98 -> 1333.18 | Y7: =W7*1000 -> 191000
A8: May | B8: =Main!D6 -> 180 | C8: =B8*295 -> 53100 | E8: May | F8: =Main!A6 -> 180 | G8: =F8*9.5 -> 1710 | H8: =F8*380 -> 68400 | V8: May | W8: =Main!H6 -> 180 | X8: =W8*6.98 -> 1256.4 | Y8: =W8*1000 -> 180000
A9: Iyun | B9: =Main!D7 -> 176 | C9: =B9*295 -> 51920 | E9: Iyun | F9: =Main!A7 -> 176 | G9: =F9*9.5 -> 1672 | H9: =F9*380 -> 66880 | V9: Iyun | W9: =Main!H7 -> 176 | X9: =W9*6.98 -> 1228.48 | Y9: =W9*1000 -> 176000
A10: Iyul | B10: =Main!D8 -> 179 | C10: =B10*295 -> 52805 | E10: Iyul | F10: =Main!A8 -> 179 | G10: =F10*9.5 -> 1700.5 | H10: =F10*380 -> 68020 | V10: Iyul | W10: =Main!H8 -> 179 | X10: =W10*6.98 -> 1249.42 | Y10: =W10*1000 -> 179000
A11: Avgust | B11: =Main!D9 -> 74 | C11: =B11*295 -> 21830 | E11: Avgust | F11: =Main!A9 -> 74 | G11: =F11*9.5 -> 703 | H11: =F11*380 -> 28120 | V11: Avgust | W11: =Main!H9 -> 74 | X11: =W11*6.98 -> 516.52 | Y11: =W11*1000 -> 74000
A12: Sentabr | B12: =Main!D10 -> 99 | C12: =B12*295 -> 29205 | E12: Sentabr | F12: =Main!A10 -> 99 | G12: =F12*9.5 -> 940.5 | H12: =F12*380 -> 37620 | V12: Sentabr | W12: =Main!H10 -> 99 | X12: =W12*6.98 -> 691.02 | Y12: =W12*1000 -> 99000
A13: Oktyabr | B13: =Main!D11 -> 131 | C13: =B13*295 -> 38645 | E13: Oktyabr | F13: =Main!A11 -> 131 | G13: =F13*9.5 -> 1244.5 | H13: =F13*380 -> 49780 | V13: Oktyabr | W13: =Main!H11 -> 131 | X13: =W13*6.98 -> 914.38 | Y13: =W13*1000 -> 131000
A14: Noyabr | B14: =Main!D12 -> 126 | C14: =B14*295 -> 37170 | E14: Noyabr | F14: =Main!A12 -> 126 | G14: =F14*9.5 -> 1197 | H14: =F14*380 -> 47880 | V14: Noyabr | W14: =Main!H12 -> 126 | X14: =W14*6.98 -> 879.48 | Y14: =W14*1000 -> 126000
A15: Dekabr | B15: =Main!D13 -> 144 | C15: =B15*295 -> 42480 | E15: Dekabr | F15: =Main!A13 -> 144 | G15: =F15*9.5 -> 1368 | H15: =F15*380 -> 54720 | V15: Dekabr | W15: =Main!H13 -> 144 | X15: =W15*6.98 -> 1005.12 | Y15: =W15*1000 -> 144000
A16: JAMI | B16: =SUM(B4:B15) -> 1716 | C16: =SUM(C4:C15) -> 506220 | E16: JAMI | F16: =SUM(F4:F15) -> 1716 | G16: =SUM(G4:G15) -> 16302 | H16: =SUM(H4:H15) -> 652080 | V16: JAMI | W16: =SUM(W4:W15) -> 1716 | X16: =SUM(X4:X15) -> 11977.68 | Y16: =SUM(Y4:Y15) -> 1716000
A17: 2024
A18: ELEKTR 2024 — Bosqichli tarif (May 1dan) | K18: GAZ 2024 — Bosqichli tarif (May 1dan)
A19: Tarif jadvali | K19: Tarif jadvali
A20: Davr | B20: 0–200 kWh | C20: 201–1000 | D20: 1001–5000 | E20: 5001–10000 | F20: 10001+ | G20: Izoh | K20: Davr | L20: Flat | M20: Kvota (m³) | N20: 0–Kvota × 650 | O20: Kvota–2500 × 1500 | P20: 2501–5000 × 1950 | Q20: 5001–10000 × 2275 | R20: 10001+ × 2600 | S20: Izoh
A21: Yan–Aprel | B21: 295 | C21: - | D21: - | E21: - | F21: - | G21: 0-200 band: 295 | K21: Yan–Apr | L21: 380 flat | M21: — | N21: — | O21: — | P21: — | Q21: — | R21: — | S21: Eski flat tarif
A22: May–Dek | B22: 450 | C22: 900 | D22: 1350 | E22: 1575 | F22: 1800 | G22: 0-200 band: 450 (May1 tarifi) | K22: May–Okt | L22: — | M22: 100 | N22: 0-100: 650 | O22: 101-2500: 1500 | P22: 2501-5000: 1950 | Q22: 5001-10k: 2275 | R22: 10001+: 2600 | S22: Isitish yo'q
K23: Nov–Feb | L23: — | M23: 500 | N23: 0-500: 650 | O23: 501-2500: 1500 | P23: 2501-5000: 1950 | Q23: 5001-10k: 2275 | R23: 10001+: 2600 | S23: Isitish mavsumi
A24: Oylik hisob-kitob | K24: Oylik hisob-kitob | V24: Boshqa 2024 — Flat 1300 so'm/kg
A25: Oy | B25: kWh | C25: 0–200 | D25: 201–1000 | E25: 1001–5000 | F25: 5001–10000 | G25: 10001+ | H25: JAMI (so'm) | K25: Oy | L25: m³ | M25: kwt/soat | N25: Kvota | O25: 0–Kvota × 650 | P25: Kvota–2500 × 1500 | Q25: 2501–5000 × 1950 | R25: 5001–10000 × 2275 | S25: 10001+ × 2600 | T25: JAMI (so'm) | V25: Oy | W25: Iste'mol (kg) | X25: kwt/soat | Y25: Xarajat (so'm)
A26: Yanvar | B26: =Main!E2 -> 127 | C26: =B26*295 -> 37465 | D26: - | E26: - | F26: - | G26: - | H26: =SUM(C26:G26) -> 37465 | K26: Yanvar | L26: =Main!B2 -> 127 | M26: =L26*9.5 -> 1206.5 | N26: — | O26: =L26*380 -> 48260 | P26: =0 -> 0 | Q26: =0 -> 0 | R26: =0 -> 0 | S26: =0 -> 0 | T26: =SUM(O26:S26) -> 48260 | V26: Yanvar | W26: =Main!I2 -> 127 | X26: =W26*6.98 -> 886.46 | Y26: =W26*1300 -> 165100
A27: Fevral | B27: =Main!E3 -> 130 | C27: =B27*295 -> 38350 | D27: - | E27: - | F27: - | G27: - | H27: =SUM(C27:G27) -> 38350 | K27: Fevral | L27: =Main!B3 -> 130 | M27: =L27*9.5 -> 1235 | N27: — | O27: =L27*380 -> 49400 | P27: =0 -> 0 | Q27: =0 -> 0 | R27: =0 -> 0 | S27: =0 -> 0 | T27: =SUM(O27:S27) -> 49400 | V27: Fevral | W27: =Main!I3 -> 130 | X27: =W27*6.98 -> 907.4 | Y27: =W27*1300 -> 169000
A28: Mart | B28: =Main!E4 -> 159 | C28: =B28*295 -> 46905 | D28: - | E28: - | F28: - | G28: - | H28: =SUM(C28:G28) -> 46905 | K28: Mart | L28: =Main!B4 -> 159 | M28: =L28*9.5 -> 1510.5 | N28: — | O28: =L28*380 -> 60420 | P28: =0 -> 0 | Q28: =0 -> 0 | R28: =0 -> 0 | S28: =0 -> 0 | T28: =SUM(O28:S28) -> 60420 | V28: Mart | W28: =Main!I4 -> 159 | X28: =W28*6.98 -> 1109.82 | Y28: =W28*1300 -> 206700
A29: Aprel | B29: =Main!E5 -> 191 | C29: =B29*295 -> 56345 | D29: - | E29: - | F29: - | G29: - | H29: =SUM(C29:G29) -> 56345 | K29: Aprel | L29: =Main!B5 -> 191 | M29: =L29*9.5 -> 1814.5 | N29: — | O29: =L29*380 -> 72580 | P29: =0 -> 0 | Q29: =0 -> 0 | R29: =0 -> 0 | S29: =0 -> 0 | T29: =SUM(O29:S29) -> 72580 | V29: Aprel | W29: =Main!I5 -> 191 | X29: =W29*6.98 -> 1333.18 | Y29: =W29*1300 -> 248300
A30: May | B30: =Main!E6 -> 180 | C30: =MIN(B30,200)*295 -> 53100 | D30: =MAX(MIN(B30,1000)-200,0)*900 -> 0 | E30: =MAX(MIN(B30,5000)-1000,0)*1350 -> 0 | F30: =MAX(MIN(B30,10000)-5000,0)*1575 -> 0 | G30: =MAX(B30-10000,0)*1800 -> 0 | H30: =SUM(C30:G30) -> 53100 | K30: May | L30: =Main!B6 -> 180 | M30: =L30*9.5 -> 1710 | N30: 100 | O30: =MIN(L30,N30)*650 -> 65000 | P30: =MAX(MIN(L30,2500)-N30,0)*1500 -> 120000 | Q30: =MAX(MIN(L30,5000)-2500,0)*1950 -> 0 | R30: =MAX(MIN(L30,10000)-5000,0)*2275 -> 0 | S30: =MAX(L30-10000,0)*2600 -> 0 | T30: =SUM(O30:S30) -> 185000 | V30: May | W30: =Main!I6 -> 180 | X30: =W30*6.98 -> 1256.4 | Y30: =W30*1300 -> 234000
A31: Iyun | B31: =Main!E7 -> 176 | C31: =MIN(B31,200)*295 -> 51920 | D31: =MAX(MIN(B31,1000)-200,0)*900 -> 0 | E31: =MAX(MIN(B31,5000)-1000,0)*1350 -> 0 | F31: =MAX(MIN(B31,10000)-5000,0)*1575 -> 0 | G31: =MAX(B31-10000,0)*1800 -> 0 | H31: =SUM(C31:G31) -> 51920 | K31: Iyun | L31: =Main!B7 -> 176 | M31: =L31*9.5 -> 1672 | N31: 100 | O31: =MIN(L31,N31)*650 -> 65000 | P31: =MAX(MIN(L31,2500)-N31,0)*1500 -> 114000 | Q31: =MAX(MIN(L31,5000)-2500,0)*1950 -> 0 | R31: =MAX(MIN(L31,10000)-5000,0)*2275 -> 0 | S31: =MAX(L31-10000,0)*2600 -> 0 | T31: =SUM(O31:S31) -> 179000 | V31: Iyun | W31: =Main!I7 -> 176 | X31: =W31*6.98 -> 1228.48 | Y31: =W31*1300 -> 228800
A32: Iyul | B32: =Main!E8 -> 179 | C32: =MIN(B32,200)*450 -> 80550 | D32: =MAX(MIN(B32,1000)-200,0)*900 -> 0 | E32: =MAX(MIN(B32,5000)-1000,0)*1350 -> 0 | F32: =MAX(MIN(B32,10000)-5000,0)*1575 -> 0 | G32: =MAX(B32-10000,0)*1800 -> 0 | H32: =SUM(C32:G32) -> 80550 | K32: Iyul | L32: =Main!B8 -> 179 | M32: =L32*9.5 -> 1700.5 | N32: 100 | O32: =MIN(L32,N32)*650 -> 65000 | P32: =MAX(MIN(L32,2500)-N32,0)*1500 -> 118500 | Q32: =MAX(MIN(L32,5000)-2500,0)*1950 -> 0 | R32: =MAX(MIN(L32,10000)-5000,0)*2275 -> 0 | S32: =MAX(L32-10000,0)*2600 -> 0 | T32: =SUM(O32:S32) -> 183500 | V32: Iyul | W32: =Main!I8 -> 179 | X32: =W32*6.98 -> 1249.42 | Y32: =W32*1300 -> 232700
A33: Avgust | B33: =Main!E9 -> 74 | C33: =MIN(B33,200)*450 -> 33300 | D33: =MAX(MIN(B33,1000)-200,0)*900 -> 0 | E33: =MAX(MIN(B33,5000)-1000,0)*1350 -> 0 | F33: =MAX(MIN(B33,10000)-5000,0)*1575 -> 0 | G33: =MAX(B33-10000,0)*1800 -> 0 | H33: =SUM(C33:G33) -> 33300 | K33: Avgust | L33: =Main!B9 -> 74 | M33: =L33*9.5 -> 703 | N33: 100 | O33: =MIN(L33,N33)*650 -> 48100 | P33: =MAX(MIN(L33,2500)-N33,0)*1500 -> 0 | Q33: =MAX(MIN(L33,5000)-2500,0)*1950 -> 0 | R33: =MAX(MIN(L33,10000)-5000,0)*2275 -> 0 | S33: =MAX(L33-10000,0)*2600 -> 0 | T33: =SUM(O33:S33) -> 48100 | V33: Avgust | W33: =Main!I9 -> 74 | X33: =W33*6.98 -> 516.52 | Y33: =W33*1300 -> 96200
A34: Sentabr | B34: =Main!E10 -> 99 | C34: =MIN(B34,200)*450 -> 44550 | D34: =MAX(MIN(B34,1000)-200,0)*900 -> 0 | E34: =MAX(MIN(B34,5000)-1000,0)*1350 -> 0 | F34: =MAX(MIN(B34,10000)-5000,0)*1575 -> 0 | G34: =MAX(B34-10000,0)*1800 -> 0 | H34: =SUM(C34:G34) -> 44550 | K34: Sentabr | L34: =Main!B10 -> 99 | M34: =L34*9.5 -> 940.5 | N34: 100 | O34: =MIN(L34,N34)*650 -> 64350 | P34: =MAX(MIN(L34,2500)-N34,0)*1500 -> 0 | Q34: =MAX(MIN(L34,5000)-2500,0)*1950 -> 0 | R34: =MAX(MIN(L34,10000)-5000,0)*2275 -> 0 | S34: =MAX(L34-10000,0)*2600 -> 0 | T34: =SUM(O34:S34) -> 64350 | V34: Sentabr | W34: =Main!I10 -> 99 | X34: =W34*6.98 -> 691.02 | Y34: =W34*1300 -> 128700
A35: Oktyabr | B35: =Main!E11 -> 131 | C35: =MIN(B35,200)*450 -> 58950 | D35: =MAX(MIN(B35,1000)-200,0)*900 -> 0 | E35: =MAX(MIN(B35,5000)-1000,0)*1350 -> 0 | F35: =MAX(MIN(B35,10000)-5000,0)*1575 -> 0 | G35: =MAX(B35-10000,0)*1800 -> 0 | H35: =SUM(C35:G35) -> 58950 | K35: Oktyabr | L35: =Main!B11 -> 131 | M35: =L35*9.5 -> 1244.5 | N35: 100 | O35: =MIN(L35,N35)*650 -> 65000 | P35: =MAX(MIN(L35,2500)-N35,0)*1500 -> 46500 | Q35: =MAX(MIN(L35,5000)-2500,0)*1950 -> 0 | R35: =MAX(MIN(L35,10000)-5000,0)*2275 -> 0 | S35: =MAX(L35-10000,0)*2600 -> 0 | T35: =SUM(O35:S35) -> 111500 | V35: Oktyabr | W35: =Main!I11 -> 131 | X35: =W35*6.98 -> 914.38 | Y35: =W35*1300 -> 170300
A36: Noyabr | B36: =Main!E12 -> 126 | C36: =MIN(B36,200)*450 -> 56700 | D36: =MAX(MIN(B36,1000)-200,0)*900 -> 0 | E36: =MAX(MIN(B36,5000)-1000,0)*1350 -> 0 | F36: =MAX(MIN(B36,10000)-5000,0)*1575 -> 0 | G36: =MAX(B36-10000,0)*1800 -> 0 | H36: =SUM(C36:G36) -> 56700 | K36: Noyabr | L36: =Main!B12 -> 126 | M36: =L36*9.5 -> 1197 | N36: 500 | O36: =MIN(L36,N36)*650 -> 81900 | P36: =MAX(MIN(L36,2500)-N36,0)*1500 -> 0 | Q36: =MAX(MIN(L36,5000)-2500,0)*1950 -> 0 | R36: =MAX(MIN(L36,10000)-5000,0)*2275 -> 0 | S36: =MAX(L36-10000,0)*2600 -> 0 | T36: =SUM(O36:S36) -> 81900 | V36: Noyabr | W36: =Main!I12 -> 126 | X36: =W36*6.98 -> 879.48 | Y36: =W36*1300 -> 163800
A37: Dekabr | B37: =Main!E13 -> 144 | C37: =MIN(B37,200)*450 -> 64800 | D37: =MAX(MIN(B37,1000)-200,0)*900 -> 0 | E37: =MAX(MIN(B37,5000)-1000,0)*1350 -> 0 | F37: =MAX(MIN(B37,10000)-5000,0)*1575 -> 0 | G37: =MAX(B37-10000,0)*1800 -> 0 | H37: =SUM(C37:G37) -> 64800 | K37: Dekabr | L37: =Main!B13 -> 144 | M37: =L37*9.5 -> 1368 | N37: 500 | O37: =MIN(L37,N37)*650 -> 93600 | P37: =MAX(MIN(L37,2500)-N37,0)*1500 -> 0 | Q37: =MAX(MIN(L37,5000)-2500,0)*1950 -> 0 | R37: =MAX(MIN(L37,10000)-5000,0)*2275 -> 0 | S37: =MAX(L37-10000,0)*2600 -> 0 | T37: =SUM(O37:S37) -> 93600 | V37: Dekabr | W37: =Main!I13 -> 144 | X37: =W37*6.98 -> 1005.12 | Y37: =W37*1300 -> 187200
A38: JAMI | B38: =SUM(B26:B37) -> 1716 | C38: =SUM(C26:C37) -> 622935 | D38: =SUM(D26:D37) -> 0 | E38: =SUM(E26:E37) -> 0 | F38: =SUM(F26:F37) -> 0 | G38: =SUM(G26:G37) -> 0 | H38: =SUM(H26:H37) -> 622935 | K38: JAMI | L38: =SUM(L26:L37) -> 1716 | M38: =SUM(M26:M37) -> 16302 | N38: — | O38: =SUM(O26:O37) -> 778610 | P38: =SUM(P26:P37) -> 399000 | Q38: =SUM(Q26:Q37) -> 0 | R38: =SUM(R26:R37) -> 0 | S38: =SUM(S26:S37) -> 0 | T38: =SUM(T26:T37) -> 1177610 | V38: JAMI | W38: =SUM(W26:W37) -> 1716 | X38: =SUM(X26:X37) -> 11977.68 | Y38: =SUM(Y26:Y37) -> 2230800
A40: Izoh: Yan–Iyun uchun 0-200 kWh×295; Iyul–Dek uchun 0-200 kWh×450; yuqori bosqichlar bir xil | K40: Izoh: Yan–Apr flat 380. May+: Nov/Dec/Jan/Feb kvota=500 m³ (isitish), qolgan oylar kvota=100 m³
K41: Bosqich 2-5 FAQAT kvotadan OSHGAN iste'mol uchun hisoblanadi
...
